Workbook

Sheet README
A1: QA Quality Evaluation — BI single-page QA (InternVL vs Qwen2.5-VL)
A3: Scope | B3: 987 QA pairs verified against their page image (495 InternVL, 492 Qwen2.5-VL) across 165 page images. 24 QA excluded (4 images missing from the folder) and 1 Qwen page produced no QA — see Not_Verified.
A4: Method | B4: Every page image was opened and each QA checked value-by-value (numbers, entity, period, unit, direction) with small labels zoomed in. Each QA got one verdict, a severity, error types, category check, evidence from the page and, for REVISE, a corrected answer.
A5: PASS | B5: Answer fully correct as written and category label fits. Needs no change.
A6: REVISE | B6: The QA is based on the page (the data/topic exists) but needs a fix: misread/misattributed number, wrong period, unit, trend direction, calculation, incomplete answer, garbled wording, or wrong category label.
A7: DISCARD | B7: Hallucinated: the question asks about something not on the page (metric, entity, period) or is unintelligible, so neither question nor answer exists in the document. A valid question with a wrong answer is REVISE-Major, not DISCARD.
A8: Severity | B8: Minor = REVISE with small fix (core fact right). Major = REVISE with a wrong key fact. Critical = DISCARD.
A9: QA Accuracy | B9: % QA whose answer is factually correct from the start. Only category-label, typo/grammar or format issues are tolerated. (Content-level view.)
A10: First Pass Yield | B10: % QA that pass with no revision at all (strict: also requires correct category label and clean wording) = PASS / N.
A11: Revision / Discard Rate | B11: REVISE / N and DISCARD / N.
A12: Error Rate | B12: % QA with at least one error = (REVISE + DISCARD) / N = 1 − FPY. Factual Error Rate = 1 − Accuracy.
A13: Error types | B13: Hallucination, Factual/Numerical (wrong or misattributed value), Calculation, Reasoning (direction/comparison/causal), Temporal (period), Unit, Incomplete, Instruction-following (category label does not fit the QA), Format, Typo/Grammar. Primary = main reason; "any" = all errors present.
A14: Categories | B14: Text-Text Inference | Chart-Information Extraction, Chart-Numerical Calculation, Chart-Time-Sensitive | Table-Numerical Calculation, Table-Comparison and Sorting. Metrics are grouped by the category the generator assigned; Suggested Category in QA_Detail gives the category that actually fits.
... A18: Sheets | B18: Summary (headline metrics, severity, error types + charts) · By_Category (every metric per category and per Text/Chart/Table) · ErrorType_x_Category · Discard_Analysis (why discarded + full list) · Revision_Analysis · QA_Detail (every QA with verdict, evidence, corrected answer; filterable) · Not_Verified.

Sheet Summary
A1: QA Quality Metrics — verified against page images
A2: Source: bi_single_final_internvl.jsonl & bi_single_qwen25_vl.jsonl; each QA checked against its page image in bi_images/single. All numbers are live formulas over QA_Detail.
A4: Model →
A5: Metric | B5: InternVL | C5: Qwen2.5-VL | D5: Overall | E5: Definition / formula
A6: QA verified (N) | B6: =COUNTIFS(QA_Detail!$B$2:$B$988,"InternVL") -> 495 | C6: =COUNTIFS(QA_Detail!$B$2:$B$988,"Qwen2.5-VL") -> 492 | D6: =COUNTIFS(QA_Detail!$B$2:$B$988,"*") -> 987 | E6: QA pairs checked against an available page image
A7: PASS (no change needed) | B7: =COUNTIFS(QA_Detail!$B$2:$B$988,"InternVL",QA_Detail!$L$2:$L$988,"PASS") -> 18 | C7: =COUNTIFS(QA_Detail!$B$2:$B$988,"Qwen2.5-VL",QA_Detail!$L$2:$L$988,"PASS") -> 104 | D7: =COUNTIFS(QA_Detail!$B$2:$B$988,"*",QA_Detail!$L$2:$L$988,"PASS") -> 122 | E7: Correct answer, correct category, no edits
A8: REVISE | B8: =COUNTIFS(QA_Detail!$B$2:$B$988,"InternVL",QA_Detail!$L$2:$L$988,"REVISE") -> 423 | C8: =COUNTIFS(QA_Detail!$B$2:$B$988,"Qwen2.5-VL",QA_Detail!$L$2:$L$988,"REVISE") -> 365 | D8: =COUNTIFS(QA_Detail!$B$2:$B$988,"*",QA_Detail!$L$2:$L$988,"REVISE") -> 788 | E8: Grounded in the page but needs a fix (value, period, unit, wording or category label)
A9: DISCARD | B9: =COUNTIFS(QA_Detail!$B$2:$B$988,"InternVL",QA_Detail!$L$2:$L$988,"DISCARD") -> 54 | C9: =COUNTIFS(QA_Detail!$B$2:$B$988,"Qwen2.5-VL",QA_Detail!$L$2:$L$988,"DISCARD") -> 23 | D9: =COUNTIFS(QA_Detail!$B$2:$B$988,"*",QA_Detail!$L$2:$L$988,"DISCARD") -> 77 | E9: Hallucinated: question AND answer not in the document
A10: Content correct | B10: =COUNTIFS(QA_Detail!$B$2:$B$988,"InternVL",QA_Detail!$R$2:$R$988,"Y") -> 64 | C10: =COUNTIFS(QA_Detail!$B$2:$B$988,"Qwen2.5-VL",QA_Detail!$R$2:$R$988,"Y") -> 232 | D10: =COUNTIFS(QA_Detail!$B$2:$B$988,"*",QA_Detail!$R$2:$R$988,"Y") -> 296 | E10: Answer factually right (only label/typo/format issues allowed)
A11: QA Accuracy | B11: =IFERROR(B10/B6,0) -> 0.12929293 | C11: =IFERROR(C10/C6,0) -> 0.47154472 | D11: =IFERROR(D10/D6,0) -> 0.29989868 | E11: % QA whose answer is factually correct from the start (ignores category label / typo / format fixes)
A12: Revision Rate | B12: =IFERROR(B8/B6,0) -> 0.85454545 | C12: =IFERROR(C8/C6,0) -> 0.74186992 | D12: =IFERROR(D8/D6,0) -> 0.79837893 | E12: % QA that need revision = REVISE / N
A13: Discard Rate | B13: =IFERROR(B9/B6,0) -> 0.10909091 | C13: =IFERROR(C9/C6,0) -> 0.046747967 | D13: =IFERROR(D9/D6,0) -> 0.078014184 | E13: % QA discarded (hallucinated) = DISCARD / N
A14: First Pass Yield (FPY) | B14: =IFERROR(B7/B6,0) -> 0.036363636 | C14: =IFERROR(C7/C6,0) -> 0.21138211 | D14: =IFERROR(D7/D6,0) -> 0.12360689 | E14: % QA that pass with zero revision of any kind (strict) = PASS / N
A15: Error Rate | B15: =IFERROR((B8+B9)/B6,0) -> 0.96363636 | C15: =IFERROR((C8+C9)/C6,0) -> 0.78861789 | D15: =IFERROR((D8+D9)/D6,0) -> 0.87639311 | E15: % QA with at least one error = (REVISE + DISCARD) / N = 1 − FPY
A16: Factual Error Rate | B16: =1-B11 -> 0.87070707 | C16: =1-C11 -> 0.52845528 | D16: =1-D11 -> 0.70010132 | E16: % QA with a content error (1 − Accuracy)
A17: Category label correct | B17: =IFERROR(COUNTIFS(QA_Detail!$B$2:$B$988,"InternVL",QA_Detail!$P$2:$P$988,"Y")/B6,0) -> 0.34343434 | C17: =IFERROR(COUNTIFS(QA_Detail!$B$2:$B$988,"Qwen2.5-VL",QA_Detail!$P$2:$P$988,"Y")/C6,0) -> 0.3699187 | D17: =IFERROR(COUNTIFS(QA_Detail!$B$2:$B$988,"*",QA_Detail!$P$2:$P$988,"Y")/D6,0) -> 0.35663627 | E17: % QA whose assigned category matches the evidence/task
A19: Error Severity
A20: Severity | B20: InternVL | C20: Qwen2.5-VL | D20: Overall | E20: % of all QA (Overall) | F20: InternVL % | G20: Qwen2.5-VL % | H20: Meaning
A21: Minor | B21: =COUNTIFS(QA_Detail!$B$2:$B$988,"InternVL",QA_Detail!$M$2:$M$988,"Minor") -> 108 | C21: =COUNTIFS(QA_Detail!$B$2:$B$988,"Qwen2.5-VL",QA_Detail!$M$2:$M$988,"Minor") -> 208 | D21: =COUNTIFS(QA_Detail!$B$2:$B$988,"*",QA_Detail!$M$2:$M$988,"Minor") -> 316 | E21: =IFERROR(D21/$D$6,0) -> 0.32016211 | F21: =IFERROR(B21/$B$6,0) -> 0.21818182 | G21: =IFERROR(C21/$C$6,0) -> 0.42276423 | H21: REVISE: core fact right; small fix (wording, unit label, period framing, category label, typo)
A22: Major | B22: =COUNTIFS(QA_Detail!$B$2:$B$988,"InternVL",QA_Detail!$M$2:$M$988,"Major") -> 315 | C22: =COUNTIFS(QA_Detail!$B$2:$B$988,"Qwen2.5-VL",QA_Detail!$M$2:$M$988,"Major") -> 157 | D22: =COUNTIFS(QA_Detail!$B$2:$B$988,"*",QA_Detail!$M$2:$M$988,"Major") -> 472 | E22: =IFERROR(D22/$D$6,0) -> 0.47821682 | F22: =IFERROR(B22/$B$6,0) -> 0.63636364 | G22: =IFERROR(C22/$C$6,0) -> 0.31910569 | H22: REVISE: key fact wrong (number / entity / period / direction / calculation) but question answerable from page
A23: Critical | B23: =COUNTIFS(QA_Detail!$B$2:$B$988,"InternVL",QA_Detail!$M$2:$M$988,"Critical") -> 54 | C23: =COUNTIFS(QA_Detail!$B$2:$B$988,"Qwen2.5-VL",QA_Detail!$M$2:$M$988,"Critical") -> 23 | D23: =COUNTIFS(QA_Detail!$B$2:$B$988,"*",QA_Detail!$M$2:$M$988,"Critical") -> 77 | E23: =IFERROR(D23/$D$6,0) -> 0.078014184 | F23: =IFERROR(B23/$B$6,0) -> 0.10909091 | G23: =IFERROR(C23/$C$6,0) -> 0.046747967 | H23: DISCARD: hallucinated, not grounded in page
A26: Error Type (primary = main reason; any = QA containing that error at all)
A27: Error Type | B27: InternVL (primary) | C27: Qwen2.5-VL (primary) | D27: Overall (primary) | E27: InternVL (any) | F27: Qwen2.5-VL (any) | G27: Overall (any) | H27: % of QA with this error (Overall)
A28: Hallucination | B28: =COUNTIFS(QA_Detail!$B$2:$B$988,"InternVL",QA_Detail!$N$2:$N$988,"Hallucination") -> 54 | C28: =COUNTIFS(QA_Detail!$B$2:$B$988,"Qwen2.5-VL",QA_Detail!$N$2:$N$988,"Hallucination") -> 23 | D28: =COUNTIFS(QA_Detail!$B$2:$B$988,"*",QA_Detail!$N$2:$N$988,"Hallucination") -> 77 | E28: =COUNTIFS(QA_Detail!$B$2:$B$988,"InternVL",QA_Detail!$Y$2:$Y$988,1) -> 55 | F28: =COUNTIFS(QA_Detail!$B$2:$B$988,"Qwen2.5-VL",QA_Detail!$Y$2:$Y$988,1) -> 23 | G28: =COUNTIFS(QA_Detail!$B$2:$B$988,"*",QA_Detail!$Y$2:$Y$988,1) -> 78 | H28: =IFERROR(G28/$D$6,0) -> 0.079027356
A29: Factual/Numerical | B29: =COUNTIFS(QA_Detail!$B$2:$B$988,"InternVL",QA_Detail!$N$2:$N$988,"Factual/Numerical") -> 234 | C29: =COUNTIFS(QA_Detail!$B$2:$B$988,"Qwen2.5-VL",QA_Detail!$N$2:$N$988,"Factual/Numerical") -> 84 | D29: =COUNTIFS(QA_Detail!$B$2:$B$988,"*",QA_Detail!$N$2:$N$988,"Factual/Numerical") -> 318 | E29: =COUNTIFS(QA_Detail!$B$2:$B$988,"InternVL",QA_Detail!$Z$2:$Z$988,1) -> 273 | F29: =COUNTIFS(QA_Detail!$B$2:$B$988,"Qwen2.5-VL",QA_Detail!$Z$2:$Z$988,1) -> 110 | G29: =COUNTIFS(QA_Detail!$B$2:$B$988,"*",QA_Detail!$Z$2:$Z$988,1) -> 383 | H29: =IFERROR(G29/$D$6,0) -> 0.38804458
A30: Calculation | B30: =COUNTIFS(QA_Detail!$B$2:$B$988,"InternVL",QA_Detail!$N$2:$N$988,"Calculation") -> 8 | C30: =COUNTIFS(QA_Detail!$B$2:$B$988,"Qwen2.5-VL",QA_Detail!$N$2:$N$988,"Calculation") -> 10 | D30: =COUNTIFS(QA_Detail!$B$2:$B$988,"*",QA_Detail!$N$2:$N$988,"Calculation") -> 18 | E30: =COUNTIFS(QA_Detail!$B$2:$B$988,"InternVL",QA_Detail!$AA$2:$AA$988,1) -> 30 | F30: =COUNTIFS(QA_Detail!$B$2:$B$988,"Qwen2.5-VL",QA_Detail!$AA$2:$AA$988,1) -> 16 | G30: =COUNTIFS(QA_Detail!$B$2:$B$988,"*",QA_Detail!$AA$2:$AA$988,1) -> 46 | H30: =IFERROR(G30/$D$6,0) -> 0.046605876
A31: Reasoning | B31: =COUNTIFS(QA_Detail!$B$2:$B$988,"InternVL",QA_Detail!$N$2:$N$988,"Reasoning") -> 46 | C31: =COUNTIFS(QA_Detail!$B$2:$B$988,"Qwen2.5-VL",QA_Detail!$N$2:$N$988,"Reasoning") -> 34 | D31: =COUNTIFS(QA_Detail!$B$2:$B$988,"*",QA_Detail!$N$2:$N$988,"Reasoning") -> 80 | E31: =COUNTIFS(QA_Detail!$B$2:$B$988,"InternVL",QA_Detail!$AB$2:$AB$988,1) -> 107 | F31: =COUNTIFS(QA_Detail!$B$2:$B$988,"Qwen2.5-VL",QA_Detail!$AB$2:$AB$988,1) -> 52 | G31: =COUNTIFS(QA_Detail!$B$2:$B$988,"*",QA_Detail!$AB$2:$AB$988,1) -> 159 | H31: =IFERROR(G31/$D$6,0) -> 0.16109422
A32: Temporal | B32: =COUNTIFS(QA_Detail!$B$2:$B$988,"InternVL",QA_Detail!$N$2:$N$988,"Temporal") -> 37 | C32: =COUNTIFS(QA_Detail!$B$2:$B$988,"Qwen2.5-VL",QA_Detail!$N$2:$N$988,"Temporal") -> 17 | D32: =COUNTIFS(QA_Detail!$B$2:$B$988,"*",QA_Detail!$N$2:$N$988,"Temporal") -> 54 | E32: =COUNTIFS(QA_Detail!$B$2:$B$988,"InternVL",QA_Detail!$AC$2:$AC$988,1) -> 123 | F32: =COUNTIFS(QA_Detail!$B$2:$B$988,"Qwen2.5-VL",QA_Detail!$AC$2:$AC$988,1) -> 35 | G32: =COUNTIFS(QA_Detail!$B$2:$B$988,"*",QA_Detail!$AC$2:$AC$988,1) -> 158 | H32: =IFERROR(G32/$D$6,0) -> 0.16008105
A33: Unit | B33: =COUNTIFS(QA_Detail!$B$2:$B$988,"InternVL",QA_Detail!$N$2:$N$988,"Unit") -> 4 | C33: =COUNTIFS(QA_Detail!$B$2:$B$988,"Qwen2.5-VL",QA_Detail!$N$2:$N$988,"Unit") -> 5 | D33: =COUNTIFS(QA_Detail!$B$2:$B$988,"*",QA_Detail!$N$2:$N$988,"Unit") -> 9 | E33: =COUNTIFS(QA_Detail!$B$2:$B$988,"InternVL",QA_Detail!$AD$2:$AD$988,1) -> 61 | F33: =COUNTIFS(QA_Detail!$B$2:$B$988,"Qwen2.5-VL",QA_Detail!$AD$2:$AD$988,1) -> 43 | G33: =COUNTIFS(QA_Detail!$B$2:$B$988,"*",QA_Detail!$AD$2:$AD$988,1) -> 104 | H33: =IFERROR(G33/$D$6,0) -> 0.10536981
A34: Incomplete | B34: =COUNTIFS(QA_Detail!$B$2:$B$988,"InternVL",QA_Detail!$N$2:$N$988,"Incomplete") -> 11 | C34: =COUNTIFS(QA_Detail!$B$2:$B$988,"Qwen2.5-VL",QA_Detail!$N$2:$N$988,"Incomplete") -> 28 | D34: =COUNTIFS(QA_Detail!$B$2:$B$988,"*",QA_Detail!$N$2:$N$988,"Incomplete") -> 39 | E34: =COUNTIFS(QA_Detail!$B$2:$B$988,"InternVL",QA_Detail!$AE$2:$AE$988,1) -> 54 | F34: =COUNTIFS(QA_Detail!$B$2:$B$988,"Qwen2.5-VL",QA_Detail!$AE$2:$AE$988,1) -> 62 | G34: =COUNTIFS(QA_Detail!$B$2:$B$988,"*",QA_Detail!$AE$2:$AE$988,1) -> 116 | H34: =IFERROR(G34/$D$6,0) -> 0.11752786
A35: Instruction-following | B35: =COUNTIFS(QA_Detail!$B$2:$B$988,"InternVL",QA_Detail!$N$2:$N$988,"Instruction-following") -> 41 | C35: =COUNTIFS(QA_Detail!$B$2:$B$988,"Qwen2.5-VL",QA_Detail!$N$2:$N$988,"Instruction-following") -> 157 | D35: =COUNTIFS(QA_Detail!$B$2:$B$988,"*",QA_Detail!$N$2:$N$988,"Instruction-following") -> 198 | E35: =COUNTIFS(QA_Detail!$B$2:$B$988,"InternVL",QA_Detail!$AF$2:$AF$988,1) -> 279 | F35: =COUNTIFS(QA_Detail!$B$2:$B$988,"Qwen2.5-VL",QA_Detail!$AF$2:$AF$988,1) -> 296 | G35: =COUNTIFS(QA_Detail!$B$2:$B$988,"*",QA_Detail!$AF$2:$AF$988,1) -> 575 | H35: =IFERROR(G35/$D$6,0) -> 0.58257345
A36: Format | B36: =COUNTIFS(QA_Detail!$B$2:$B$988,"InternVL",QA_Detail!$N$2:$N$988,"Format") -> 6 | C36: =COUNTIFS(QA_Detail!$B$2:$B$988,"Qwen2.5-VL",QA_Detail!$N$2:$N$988,"Format") -> 5 | D36: =COUNTIFS(QA_Detail!$B$2:$B$988,"*",QA_Detail!$N$2:$N$988,"Format") -> 11 | E36: =COUNTIFS(QA_Detail!$B$2:$B$988,"InternVL",QA_Detail!$AG$2:$AG$988,1) -> 35 | F36: =COUNTIFS(QA_Detail!$B$2:$B$988,"Qwen2.5-VL",QA_Detail!$AG$2:$AG$988,1) -> 34 | G36: =COUNTIFS(QA_Detail!$B$2:$B$988,"*",QA_Detail!$AG$2:$AG$988,1) -> 69 | H36: =IFERROR(G36/$D$6,0) -> 0.069908815
A37: Typo/Grammar | B37: =COUNTIFS(QA_Detail!$B$2:$B$988,"InternVL",QA_Detail!$N$2:$N$988,"Typo/Grammar") -> 36 | C37: =COUNTIFS(QA_Detail!$B$2:$B$988,"Qwen2.5-VL",QA_Detail!$N$2:$N$988,"Typo/Grammar") -> 25 | D37: =COUNTIFS(QA_Detail!$B$2:$B$988,"*",QA_Detail!$N$2:$N$988,"Typo/Grammar") -> 61 | E37: =COUNTIFS(QA_Detail!$B$2:$B$988,"InternVL",QA_Detail!$AH$2:$AH$988,1) -> 198 | F37: =COUNTIFS(QA_Detail!$B$2:$B$988,"Qwen2.5-VL",QA_Detail!$AH$2:$AH$988,1) -> 100 | G37: =COUNTIFS(QA_Detail!$B$2:$B$988,"*",QA_Detail!$AH$2:$AH$988,1) -> 298 | H37: =IFERROR(G37/$D$6,0) -> 0.30192503
A38: Total QA with errors | B38: =SUM(B28:B37) -> 477 | C38: =SUM(C28:C37) -> 388 | D38: =SUM(D28:D37) -> 865
A39: Primary counts sum to REVISE+DISCARD; "any" counts overlap because one QA can carry several errors.

Sheet QA_Detail
A1: QA_ID | B1: Model | C1: Document | D1: Page | E1: Image File | F1: Gen Idx | G1: Assigned Category | H1: Modality | I1: Question | J1: Answer | K1: Answer Type | L1: Verdict | M1: Severity | N1: Primary Error Type | O1: All Error Types | P1: Category Correct | Q1: Suggested Category | R1: Content Correct | S1: Discard Reason | T1: Discard Answer Basis | U1: Evidence on Page | V1: Reviewer Explanation | W1: Corrected Question | X1: Corrected Answer | Y1: ERR: Hallucination | Z1: ERR: Factual/Numerical | AA1: ERR: Calculation | AB1: ERR: Reasoning | AC1: ERR: Temporal | AD1: ERR: Unit | AE1: ERR: Incomplete | AF1: ERR: Instruction-following | AG1: ERR: Format | AH1: ERR: Typo/Grammar
A2: QA0001 | B2: InternVL | C2: KERProvinsiKalimantanTengahTriwulanIV2012 | D2: 13 | E2: 8dabadfb728f43cf89fe3bf6bb7614a3KERProvinsiKalimantanTengahTriwulanIV2012_p013.png | F2: 0 | G2: Text-Text Inference | H2: Text | I2: Bagaimana kondisi umum ekspor di Kalimantan Tengah selama periode 2005-2012? | J2: Ekspor di Kalimantan Tengah selama periode 2005-2012 meningkat dari 33,64 miliar rupiah pada tahun 2005 menjadi 55,38 miliar rupiah pada tahun 2012. | K2: pendek | L2: REVISE | M2: Major | N2: Factual/Numerical | O2: Factual/Numerical, Unit, Instruction-following | P2: N | Q2: Table-Comparison and Sorting | R2: N | U2: Tabel 1.1: Ekspor share of PDRB 33,64% (2005) -> 42,61% (2012); 55,38 is Impor 2011. Values are % shares, not miliar rupiah. | V2: 2012 value wrong (55,38 is Impor 2011), unit wrong (% share not miliar rupiah), and evidence is in the table, not text. | X2: Pangsa ekspor terhadap PDRB Kalimantan Tengah meningkat dari 33,64% pada tahun 2005 menjadi 42,61% pada tahun 2012 (sempat mencapai 44,56% pada 2011). | Y2: 0 | Z2: 1 | AA2: 0 | AB2: 0 | AC2: 0 | AD2: 1 | AE2: 0 | AF2: 1 | AG2: 0 | AH2: 0
A3: QA0002 | B3: InternVL | C3: KERProvinsiKalimantanTengahTriwulanIV2012 | D3: 13 | E3: 8dabadfb728f43cf89fe3bf6bb7614a3KERProvinsiKalimantanTengahTriwulanIV2012_p013.png | F3: 1 | G3: Chart-Numerical Calculation | H3: Chart | I3: Bagaimana pertumbuhan ekonomi di Kalimantan Tengah selama periode 2005-2012? | J3: Pertumbuhan ekonomi di Kalimantan Tengah selama periode 2005-2012 mencapai 6,62% (yoy). | K3: panjang | L3: REVISE | M3: Minor | N3: Temporal | O3: Temporal, Instruction-following | P3: N | Q3: Text-Text Inference | R3: N | U3: Text: ekonomi Kalteng triwulan IV-2012 tumbuh 6,62% (yoy), melambat dari 7,14% periode lalu. No chart on page. | V3: 6,62% yoy is Tw IV-2012 growth, not 2005-2012; page has no chart so Chart-Numerical Calculation label is wrong. | W3: Bagaimana pertumbuhan ekonomi Kalimantan Tengah pada triwulan IV-2012? | X3: Perekonomian Kalimantan Tengah pada triwulan IV-2012 tumbuh 6,62% (yoy), melambat dibanding periode sebelumnya yang tumbuh 7,14%. | Y3: 0 | Z3: 0 | AA3: 0 | AB3: 0 | AC3: 1 | AD3: 0 | AE3: 0 | AF3: 1 | AG3: 0 | AH3: 0
A4: QA0003 | B4: InternVL | C4: KERProvinsiKalimantanTengahTriwulanIV2012 | D4: 13 | E4: 8dabadfb728f43cf89fe3bf6bb7614a3KERProvinsiKalimantanTengahTriwulanIV2012_p013.png | F4: 2 | G4: Chart-Time-Sensitive | H4: Chart | I4: Bagaimana pertumbuhan investasi di Kalimantan Tengah selama periode 2005-2012? | J4: Investasi di Kalimantan Tengah selama periode 2005-2012 meningkat dari 5,56 miliar rupiah pada tahun 2005 menjadi 27,99 miliar rupiah pada tahun 2012. | K4: pendek | L4: REVISE | M4: Major | N4: Factual/Numerical | O4: Factual/Numerical, Unit, Instruction-following | P4: N | Q4: Table-Comparison and Sorting | R4: N | U4: Tabel 1.1: Pembentukan Modal Tetap Bruto (investasi) share 35,91% (2005) -> 46,44% (2012). 27,99 is Pertanian 2012. No chart. | V4: Values wrong (5,56 and 27,99 are not investment figures), unit should be % share of PDRB, and data is from a table not a chart. | X4: Pangsa investasi (PMTB) terhadap PDRB Kalimantan Tengah meningkat dari 35,91% pada tahun 2005 menjadi 46,44% pada tahun 2012. | Y4: 0 | Z4: 1 | AA4: 0 | AB4: 0 | AC4: 0 | AD4: 1 | AE4: 0 | AF4: 1 | AG4: 0 | AH4: 0
A5: QA0004 | B5: InternVL | C5: KERProvinsiKalimantanTengahTriwulanIV2012 | D5: 16 | E5: 8dabadfb728f43cf89fe3bf6bb7614a3KERProvinsiKalimantanTengahTriwulanIV2012_p016.png | F5: 0 | G5: Text-Text Inference | H5: Text | I5: Bagaimana kinerja kredit konsumsi lainnya pada tahun 2011? | J5: Kredit konsumsi lainnya meningkat 4,867 miliar rupiah | K5: pendek | L5: REVISE | M5: Major | N5: Factual/Numerical | O5: Factual/Numerical, Unit, Reasoning, Instruction-following | P5: N | Q5: Chart-Time-Sensitive | R5: N | U5: Grafik 1.3 (%yoy): Kredit Konsumsi Lainnya ~34% (Jan-2011), ~27% until Jul-2011, dropped to ~10% in Aug and ~10-13% to Dec-2011. No 4,867 miliar anywhere. | V5: The series exists only in Grafik 1.3 as % yoy growth; the answer's 4,867 miliar is fabricated with wrong unit, and growth actually slowed during 2011. Evidence is chart, not text. | X5: Pertumbuhan kredit konsumsi lainnya melambat sepanjang 2011, dari sekitar 34% (yoy) di awal tahun, stabil sekitar 27% hingga Juli, lalu turun ke kisaran 10-13% (yoy) sejak Agustus hingga akhir 2011. | Y5: 0 | Z5: 1 | AA5: 0 | AB5: 1 | AC5: 0 | AD5: 1 | AE5: 0 | AF5: 1 | AG5: 0 | AH5: 0
A6: QA0005 | B6: InternVL | C6: KERProvinsiKalimantanTengahTriwulanIV2012 | D6: 16 | E6: 8dabadfb728f43cf89fe3bf6bb7614a3KERProvinsiKalimantanTengahTriwulanIV2012_p016.png | F6: 1 | G6: Chart-Numerical Calculation | H6: Chart | I6: Bagaimana kontribusi K/L pada tahun 2011? | J6: K/L mengkontribusi 97% dari total anggaran belanja | K6: panjang | L6: REVISE | M6: Minor | N6: Temporal | O6: Temporal, Instruction-following | P6: N | Q6: Text-Text Inference | R6: N | U6: Text & Tabel 1.3: Anggaran K/L terealisasi Rp4,74 triliun atau sekitar 97% dari total anggaran belanja pusat untuk K/L di Kalteng, at Tw IV-2012 (2012 Q4). No 2011 K/L figure. | V6: 97% is K/L budget realization in Q4 2012, not 2011 and not a 'contribution'; no chart or calculation involved. | W6: Berapa realisasi anggaran K/L (APBN) di Kalimantan Tengah pada triwulan IV 2012? | X6: Anggaran K/L terealisasi sebesar Rp4,74 triliun atau sekitar 97% dari total anggaran belanja pusat yang dialokasikan untuk Kementerian dan Lembaga di Kalimantan Tengah. | Y6: 0 | Z6: 0 | AA6: 0 | AB6: 0 | AC6: 1 | AD6: 0 | AE6: 0 | AF6: 1 | AG6: 0 | AH6: 0
A7: QA0006 | B7: InternVL | C7: KERProvinsiKalimantanTengahTriwulanIV2012 | D7: 16 | E7: 8dabadfb728f43cf89fe3bf6bb7614a3KERProvinsiKalimantanTengahTriwulanIV2012_p016.png | F7: 2 | G7: Chart-Time-Sensitive | H7: Chart | I7: Bagaimana pertumbuhan investasi fisik pada tahun 2011? | J7: Investasi fisik meningkat 4,26% | K7: pendek | L7: REVISE | M7: Major | N7: Factual/Numerical | O7: Factual/Numerical, Temporal, Instruction-following | P7: N | Q7: Text-Text Inference | R7: N | U7: Text 1.2.2: PMTB tumbuh 17,59% (Tw IV-2012), up from 10,55% (yoy) in Tw III; contribution rose from 4,26% to 7,54%. No 2011 data; no chart on investment. | V7: 4,26% is the Tw III-2012 contribution to growth, not investment growth, and not 2011. Evidence is running text, not a chart. | W7: Bagaimana pertumbuhan investasi fisik (PMTB) Kalimantan Tengah pada triwulan IV 2012? | X7: Investasi PMTB tumbuh 17,59% (yoy), lebih tinggi dari triwulan III sebesar 10,55% (yoy), dengan kontribusi pertumbuhan meningkat dari 4,26% menjadi 7,54%. | Y7: 0 | Z7: 1 | AA7: 0 | AB7: 0 | AC7: 1 | AD7: 0 | AE7: 0 | AF7: 1 | AG7: 0 | AH7: 0
A8: QA0007 | B8: InternVL | C8: KERProvinsiKalimantanTengahTriwulanIV2012 | D8: 17 | E8: 8dabadfb728f43cf89fe3bf6bb7614a3KERProvinsiKalimantanTengahTriwulanIV2012_p017.png | F8: 0 | G8: Text-Text Inference | H8: Text | I8: Bagaimana perubahan ekspor di Kalimantan Tengah selama periode IV-2012? | J8: Ekspor di Kalimantan Tengah selama periode IV-2012 meningkat 43,5% dari tahun sebelumnya. | K8: pendek | L8: REVISE | M8: Major | N8: Reasoning | O8: Reasoning | P8: Y | Q8: Text-Text Inference | R8: N | U8: Text: transaksi ekspor luar negeri Tw IV-2012 US$211,38 juta atau turun 43,5% (yoy). | V8: Magnitude 43,5% is right but direction is wrong: exports fell (turun), not rose. | X8: Ekspor luar negeri Kalimantan Tengah pada triwulan IV-2012 sebesar US$211,38 juta atau turun 43,5% (yoy). | Y8: 0 | Z8: 0 | AA8: 0 | AB8: 1 | AC8: 0 | AD8: 0 | AE8: 0 | AF8: 0 | AG8: 0 | AH8: 0
A9: QA0008 | B9: InternVL | C9: KERProvinsiKalimantanTengahTriwulanIV2012 | D9: 17 | E9: 8dabadfb728f43cf89fe3bf6bb7614a3KERProvinsiKalimantanTengahTriwulanIV2012_p017.png | F9: 1 | G9: Chart-Numerical Calculation | H9: Chart | I9: Bagaimana perubahan import di Kalimantan Tengah selama periode IV-2012? | J9: Import di Kalimantan Tengah selama periode IV-2012 meningkat 143,1% dari tahun sebelumnya. | K9: pendek | L9: REVISE | M9: Major | N9: Factual/Numerical | O9: Factual/Numerical, Reasoning, Instruction-following | P9: N | Q9: Text-Text Inference | R9: N | U9: Text: pertumbuhan impor menurun dari 313,9% menjadi -36,0% (US$29,71 juta); volume impor turun dari 143,1% menjadi -61,7%. | V9: 143,1% is the previous-quarter volume growth; in Tw IV-2012 imports contracted (-36,0% value, -61,7% volume). Info is from text, not a chart calculation. | X9: Impor Kalimantan Tengah pada triwulan IV-2012 menurun: pertumbuhan nilai impor turun dari 313,9% menjadi -36,0% (total US$29,71 juta) dan volume impor turun dari 143,1% menjadi -61,7%. | Y9: 0 | Z9: 1 | AA9: 0 | AB9: 1 | AC9: 0 | AD9: 0 | AE9: 0 | AF9: 1 | AG9: 0 | AH9: 0
A10: QA0009 | B10: InternVL | C10: KERProvinsiKalimantanTengahTriwulanIV2012 | D10: 17 | E10: 8dabadfb728f43cf89fe3bf6bb7614a3KERProvinsiKalimantanTengahTriwulanIV2012_p017.png | F10: 2 | G10: Chart-Information Extraction | H10: Chart | I10: Bagaimana perubahan kredit investasi di Kalimantan Tengah selama periode IV-2012? | J10: Kredit investasi di Kalimantan Tengah selama periode IV-2012 meningkat 58% dari tahun sebelumnya. | K10: panjang | L10: REVISE | M10: Major | N10: Factual/Numerical | O10: Factual/Numerical | P10: Y | Q10: Chart-Information Extraction | R10: N | U10: Grafik 1.8: kredit investasi Tw IV-2012 ~Rp5,3 triliun (naik dari ~Rp4,7 triliun); garis rata-rata tahunan ~15%. | V10: No 58% growth shown; chart shows credit rising to ~Rp5,3 triliun with growth line around ~15% in Tw IV-2012. | X10: Kredit investasi perbankan Kalimantan Tengah pada triwulan IV-2012 meningkat menjadi sekitar Rp5,3 triliun (dari sekitar Rp4,7 triliun pada triwulan III), dengan pertumbuhan sekitar 15%. | Y10: 0 | Z10: 1 | AA10: 0 | AB10: 0 | AC10: 0 | AD10: 0 | AE10: 0 | AF10: 0 | AG10: 0 | AH10: 0
A11: QA0010 | B11: InternVL | C11: KERProvinsiKalimantanTengahTriwulanIV2012 | D11: 19 | E11: 8dabadfb728f43cf89fe3bf6bb7614a3KERProvinsiKalimantanTengahTriwulanIV2012_p019.png | F11: 0 | G11: Chart-Time-Sensitive | H11: Chart | I11: Bagaimana perubahan ekspor batubara di Kalimantan selama periode 2011 dan 2012? | J11: Ekspor batubara di Kalimantan meningkat dari 328 ton pada tahun 2011 menjadi 548 ribu pada tahun 2012. | K11: pendek | L11: REVISE | M11: Minor | N11: Instruction-following | O11: Instruction-following, Unit, Incomplete | P11: N | Q11: Text-Text Inference | R11: N | U11: Text: rata-rata ekspor 3 perusahaan (AKT, Merunda Graha Mineral, Multi Tambang Jaya Utama) 2012 diestimasi 548 ribu ton vs 2011 tercatat 328 ton. | V11: Values match text but they are avg exports of 3 large companies in Kalteng (not all Kalimantan), unit 'ton' missing after 548 ribu, and source is paragraph not chart. | W11: Bagaimana perubahan rata-rata ekspor batubara dari 3 perusahaan besar di Kalimantan Tengah pada tahun 2011 dan 2012? | X11: Rata-rata ekspor dari 3 perusahaan besar (PT Asmin Koalindo Tuhup, Merunda Graha Mineral, dan Multi Tambang Jaya Utama) meningkat dari 328 ton (sebagaimana tertulis) pada tahun 2011 menjadi sekitar 548 ribu ton pada tahun 2012. | Y11: 0 | Z11: 0 | AA11: 0 | AB11: 0 | AC11: 0 | AD11: 1 | AE11: 1 | AF11: 1 | AG11: 0 | AH11: 0
A12: QA0011 | B12: InternVL | C12: KERProvinsiKalimantanTengahTriwulanIV2012 | D12: 19 | E12: 8dabadfb728f43cf89fe3bf6bb7614a3KERProvinsiKalimantanTengahTriwulanIV2012_p019.png | F12: 1 | G12: Chart-Numerical Calculation | H12: Chart | I12: Bagaimana kontribusi ekspor batubara ke China di tahun 2011 dan 2012? | J12: Pada tahun 2011, kontribusi ekspor batubara ke China adalah 38,1%, dan pada tahun 2012, menjadi 41,8%. | K12: panjang | L12: REVISE | M12: Major | N12: Factual/Numerical | O12: Factual/Numerical, Instruction-following | P12: N | Q12: Text-Text Inference | R12: N | U12: Text: ekspor ke Jepang 2011 38,1%, ke China 28,5%; 2012 (Jan-Sep) Jepang 29,2%, China 41,8% dari total ekspor batubara Kalteng. | V12: China 2011 share is 28,5%, not 38,1% (that is Jepang). Shares are stated in text, no calculation from chart. | X12: Kontribusi ekspor batubara ke China sebesar 28,5% dari total ekspor batubara Kalteng pada tahun 2011 dan meningkat menjadi 41,8% pada tahun 2012 (Jan-Sep). | Y12: 0 | Z12: 1 | AA12: 0 | AB12: 0 | AC12: 0 | AD12: 0 | AE12: 0 | AF12: 1 | AG12: 0 | AH12: 0
A13: QA0012 | B13: InternVL | C13: KERProvinsiKalimantanTengahTriwulanIV2012 | D13: 19 | E13: 8dabadfb728f43cf89fe3bf6bb7614a3KERProvinsiKalimantanTengahTriwulanIV2012_p019.png | F13: 2 | G13: Chart-Information Extraction | H13: Chart | I13: Bagaimana perubahan ekspor batubara dari India, Jepang, dan China pada tahun 2011? | J13: Pada tahun 2011, India, Jepang, dan China mengkontribusi sebesar-besarnya ke ekspor batubara di Kalimantan, dengan India 38,1%, Jepang 28,5%, dan China 41,8%. | K13: pendek | L13: REVISE | M13: Major | N13: Factual/Numerical | O13: Factual/Numerical, Typo/Grammar, Instruction-following | P13: N | Q13: Text-Text Inference | R13: N | U13: Text: 2011 share Jepang 38,1%, China 28,5%; India only described as cenderung stabil (no share). 41,8% is China 2012. | V13: Shares misattributed: Jepang 38,1%, China 28,5% in 2011; 41,8% is China 2012; no India share on page. Question says 'ekspor dari' countries (they are destinations). | W13: Berapa kontribusi ekspor batubara Kalteng ke Jepang dan China pada tahun 2011, dan bagaimana ekspor ke India? | X13: Pada tahun 2011, ekspor batubara ke Jepang mencapai 38,1% dan ke China 28,5% dari total ekspor batubara Kalteng, sedangkan ekspor ke India cenderung stabil. | Y13: 0 | Z13: 1 | AA13: 0 | AB13: 0 | AC13: 0 | AD13: 0 | AE13: 0 | AF13: 1 | AG13: 0 | AH13: 1
A14: QA0013 | B14: InternVL | C14: KERProvinsiKalimantanTengahTriwulanIV2012 | D14: 21 | E14: 8dabadfb728f43cf89fe3bf6bb7614a3KERProvinsiKalimantanTengahTriwulanIV2012_p021.png | F14: 0 | G14: Chart-Numerical Calculation | H14: Chart | I14: Bagaimana kontribusi PDRB pada sektor pertamanya di periode ini? | J14: Kontribusi PDRB sektor pertamanya adalah 0.79% | K14: pendek | L14: REVISE | M14: Minor | N14: Instruction-following | O14: Instruction-following, Typo/Grammar | P14: N | Q14: Text-Text Inference | R14: Y | U14: Tabel 1.4 Kontribusi Pertanian IV-12 = 0.79; text: sumbangan pertanian turun dari 1,98% menjadi 0,79%. No chart on page. | V14: Value 0.79% is correct for Pertanian (first sector) in Tw IV-2012, but no chart/calculation involved (table/text lookup) and 'sektor pertamanya' is garbled. | W14: Berapa kontribusi (sumbangan pertumbuhan) sektor pertanian terhadap PDRB Kalimantan Tengah pada triwulan IV-2012? | X14: Sumbangan sektor pertanian terhadap pertumbuhan PDRB pada triwulan IV-2012 sebesar 0,79%, turun dari 1,98% pada triwulan sebelumnya. | Y14: 0 | Z14: 0 | AA14: 0 | AB14: 0 | AC14: 0 | AD14: 0 | AE14: 0 | AF14: 1 | AG14: 0 | AH14: 1
A15: QA0014 | B15: InternVL | C15: KERProvinsiKalimantanTengahTriwulanIV2012 | D15: 21 | E15: 8dabadfb728f43cf89fe3bf6bb7614a3KERProvinsiKalimantanTengahTriwulanIV2012_p021.png | F15: 1 | G15: Chart-Information Extraction | H15: Chart | I15: Bagaimana pertumbuhan produk di Kalimantan Tengah selama periode ini? | J15: Pertumbuhan produk di Kalimantan Tengah selama periode ini adalah 2,88% | K15: panjang | L15: REVISE | M15: Major | N15: Factual/Numerical | O15: Factual/Numerical, Instruction-following, Typo/Grammar | P15: N | Q15: Table-Comparison and Sorting | R15: N | U15: Tabel 1.4: PDRB Kalteng growth IV-12 = 6.62 (III-12 7.14). 2.88 is Pertanian growth IV-12. No chart. | V15: Kalteng (PDRB) growth in Tw IV-2012 is 6,62%, not 2,88% (that is the agriculture sector). Question vague ('produk'); data from table not chart; pure lookup has no exact label. | W15: Berapa pertumbuhan PDRB Kalimantan Tengah pada triwulan IV-2012? | X15: PDRB Kalimantan Tengah tumbuh 6,62% (yoy) pada triwulan IV-2012, melambat dari 7,14% pada triwulan III-2012. | Y15: 0 | Z15: 1 | AA15: 0 | AB15: 0 | AC15: 0 | AD15: 0 | AE15: 0 | AF15: 1 | AG15: 0 | AH15: 1
A16: QA0015 | B16: InternVL | C16: KERProvinsiKalimantanTengahTriwulanIV2012 | D16: 21 | E16: 8dabadfb728f43cf89fe3bf6bb7614a3KERProvinsiKalimantanTengahTriwulanIV2012_p021.png | F16: 2 | G16: Text-Text Inference | H16: Text | I16: Bagaimana pertumbuhan produk di sektor pertamanya di periode ini dibandingkan dengan sektor lainnya? | J16: Pertumbuhan produk di sektor pertamanya lebih rendah dibandingkan dengan sektor lainnya | K16: pendek | L16: REVISE | M16: Minor | N16: Reasoning | O16: Reasoning, Instruction-following, Typo/Grammar | P16: N | Q16: Table-Comparison and Sorting | R16: N | U16: Tabel 1.4 growth IV-12: Pertanian 2.88; Industri pengolahan 1.04 (lower); others 4.48-15.36; PDRB 6.62. | V16: Pertanian growth (2,88%) is lower than PDRB and most sectors but not all: Industri pengolahan (1,04%) is lower. Comparison uses table, not text. | W16: Bagaimana pertumbuhan sektor pertanian pada triwulan IV-2012 dibandingkan sektor lainnya? | X16: Pertumbuhan sektor pertanian (2,88%) lebih rendah dibanding PDRB (6,62%) dan sebagian besar sektor lain, namun masih di atas sektor industri pengolahan (1,04%). | Y16: 0 | Z16: 0 | AA16: 0 | AB16: 1 | AC16: 0 | AD16: 0 | AE16: 0 | AF16: 1 | AG16: 0 | AH16: 1
A17: QA0016 | B17: InternVL | C17: KERProvinsiKalimantanTengahTriwulanIV2012 | D17: 38 | E17: 8dabadfb728f43cf89fe3bf6bb7614a3KERProvinsiKalimantanTengahTriwulanIV2012_p038.png | F17: 0 | G17: Chart-Numerical Calculation | H17: Chart | I17: Bagaimana perubahan nilai Pertumbuhan Dana Pihak Ketiga (DPK) di Kota Palangka Raya selama periode IV-2012? | J17: Pertumbuhan Dana Pihak Ketiga (DPK) meningkat dari 18,47% menjadi 19,80% | K17: pendek | L17: REVISE | M17: Major | N17: Reasoning | O17: Reasoning, Factual/Numerical, Instruction-following | P17: N | Q17: Text-Text Inference | R17: N | U17: Text 3.1.3: DPK Kalteng Tw IV-2012 tumbuh 19,80% (yoy), melambat dari 28,15% periode sebelumnya; 18,47% adalah rata-rata historis 5 tahun. No chart. | V17: Growth slowed (28,15% -> 19,80%), not increased; 18,47% is the 5-year average. Data is for Kalteng province, not Kota Palangka Raya. No chart on page; evidence is text. | W17: Bagaimana perubahan pertumbuhan Dana Pihak Ketiga (DPK) perbankan Kalimantan Tengah pada triwulan IV-2012? | X17: Pertumbuhan DPK melambat dari 28,15% pada periode sebelumnya menjadi 19,80% (yoy) pada triwulan IV-2012, meskipun masih di atas rata-rata historis 5 tahun sebesar 18,47%. | Y17: 0 | Z17: 1 | AA17: 0 | AB17: 1 | AC17: 0 | AD17: 0 | AE17: 0 | AF17: 1 | AG17: 0 | AH17: 0
A18: QA0017 | B18: InternVL | C18: KERProvinsiKalimantanTengahTriwulanIV2012 | D18: 38 | E18: 8dabadfb728f43cf89fe3bf6bb7614a3KERProvinsiKalimantanTengahTriwulanIV2012_p038.png | F18: 1 | G18: Chart-Time-Sensitive | H18: Chart | I18: Bagaimana perubahan nilai Pertumbuhan Dana Jenis Tabungan (DPK) di Kota Palangka Raya selama periode IV-2012? | J18: Pertumbuhan Dana Jenis Tabungan meningkat dari 54,5% menjadi 54,7% | K18: panjang | L18: REVISE | M18: Major | N18: Factual/Numerical | O18: Factual/Numerical, Reasoning, Instruction-following | P18: N | Q18: Text-Text Inference | R18: N | U18: Text: pertumbuhan dana jenis tabungan melambat dari 21,9% menjadi 19,9%; 54,5% is tabungan share of DPK (Tabel 3.3: 54,4% Des-11, 54,5% Des-12). Kalteng, no chart. | V18: 54,5% is the composition share, not growth; 54,7% does not exist. Tabungan growth slowed 21,9% -> 19,9%. Entity is Kalteng not Palangka Raya. No chart. | W18: Bagaimana perubahan pertumbuhan dana jenis tabungan perbankan Kalimantan Tengah pada triwulan IV-2012? | X18: Pertumbuhan dana jenis tabungan melambat dari 21,9% menjadi 19,9%, disebabkan turunnya porsi tabungan sektor swasta. | Y18: 0 | Z18: 1 | AA18: 0 | AB18: 1 | AC18: 0 | AD18: 0 | AE18: 0 | AF18: 1 | AG18: 0 | AH18: 0
A19: QA0018 | B19: InternVL | C19: KERProvinsiKalimantanTengahTriwulanIV2012 | D19: 38 | E19: 8dabadfb728f43cf89fe3bf6bb7614a3KERProvinsiKalimantanTengahTriwulanIV2012_p038.png | F19: 2 | G19: Text-Text Inference | H19: Text | I19: Bagaimana perubahan nilai Pertumbuhan Dana Deposito di Kota Palangka Raya selama periode IV-2012? | J19: Pertumbuhan Dana Deposito meningkat dari 17,8% menjadi 18,0% | K19: pendek | L19: REVISE | M19: Major | N19: Factual/Numerical | O19: Factual/Numerical, Reasoning | P19: Y | Q19: Text-Text Inference | R19: N | U19: Text: deposito tumbuh 6,43% (yoy) pada Tw IV-2012 vs 8,31% di Tw III; 17,8% is deposito share of DPK. | V19: Deposito growth slowed from 8,31% to 6,43% yoy; answer uses composition share 17,8% and invented 18,0% with wrong direction. Entity is Kalteng, not Palangka Raya. | W19: Bagaimana perubahan pertumbuhan deposito perbankan Kalimantan Tengah pada triwulan IV-2012? | X19: Pertumbuhan deposito melambat dari 8,31% (yoy) pada triwulan III menjadi 6,43% (yoy) pada triwulan IV-2012. | Y19: 0 | Z19: 1 | AA19: 0 | AB19: 1 | AC19: 0 | AD19: 0 | AE19: 0 | AF19: 0 | AG19: 0 | AH19: 0
A20: QA0019 | B20: InternVL | C20: KERProvinsiKalimantanTengahTriwulanIV2012 | D20: 40 | E20: 8dabadfb728f43cf89fe3bf6bb7614a3KERProvinsiKalimantanTengahTriwulanIV2012_p040.png | F20: 0 | G20: Chart-Time-Sensitive | H20: Chart | I20: Bagaimana perubahan kredit ekonomi selama periode IV-2012? | J20: Kredit ekonomi meningkat sebesar 29,46% selama periode IV-2012 | K20: pendek | L20: REVISE | M20: Major | N20: Factual/Numerical | O20: Factual/Numerical, Typo/Grammar, Instruction-following | P20: N | Q20: Text-Text Inference | R20: N | U20: No 29,46% on page. Text: kredit perdagangan tumbuh 40,30% (rata-rata historis 29,26%), jasa-jasa 77,46%, modal kerja 46,37% (yoy) Tw IV-2012. | V20: 'Kredit ekonomi' is vague; 29,46% not on page (likely misread of 29,26%, the historical average of perdagangan credit). Sector growth figures come from text, not chart. | W20: Berapa pertumbuhan kredit sektor perdagangan di Kalteng pada triwulan IV-2012? | X20: Kredit sektor perdagangan tumbuh 40,30% (yoy) pada triwulan IV-2012, di atas rata-rata historisnya sebesar 29,26%. | Y20: 0 | Z20: 1 | AA20: 0 | AB20: 0 | AC20: 0 | AD20: 0 | AE20: 0 | AF20: 1 | AG20: 0 | AH20: 1
A21: QA0020 | B21: InternVL | C21: KERProvinsiKalimantanTengahTriwulanIV2012 | D21: 40 | E21: 8dabadfb728f43cf89fe3bf6bb7614a3KERProvinsiKalimantanTengahTriwulanIV2012_p040.png | F21: 1 | G21: Chart-Numerical Calculation | H21: Chart | I21: Bagaimana perubahan kredit konsumsi selama periode IV-2012? | J21: Kredit konsumsi meningkat 40,30% selama periode IV-2012 | K21: panjang | L21: REVISE | M21: Major | N21: Factual/Numerical | O21: Factual/Numerical, Instruction-following | P21: N | Q21: Chart-Time-Sensitive | R21: N | U21: 40,30% is kredit sektor perdagangan (text). Grafik 3.4: kredit konsumsi relatif konstan ~20-25% yoy; text: pertumbuhan kredit konsumsi relatif konstan. | V21: Wrong series: 40,30% belongs to perdagangan credit. Consumption credit growth is described as relatively constant (~24% yoy at end of Grafik 3.4). No calculation involved. | X21: Pertumbuhan kredit konsumsi relatif konstan (sekitar 20-25% yoy pada Grafik 3.4), sehingga pangsa kredit konsumsi kembali dominan pada periode laporan. | Y21: 0 | Z21: 1 | AA21: 0 | AB21: 0 | AC21: 0 | AD21: 0 | AE21: 0 | AF21: 1 | AG21: 0 | AH21: 0
A22: QA0021 | B22: InternVL | C22: KERProvinsiKalimantanTengahTriwulanIV2012 | D22: 40 | E22: 8dabadfb728f43cf89fe3bf6bb7614a3KERProvinsiKalimantanTengahTriwulanIV2012_p040.png | F22: 2 | G22: Text-Text Inference | H22: Text | I22: Bagaimana kredit modal terhadap kredit investasi selama periode IV-2012? | J22: Kredit modal lebih tinggi dibandingkan kredit investasi selama periode IV-2012 | K22: pendek | L22: REVISE | M22: Minor | N22: Typo/Grammar | O22: Typo/Grammar, Incomplete | P22: Y | Q22: Text-Text Inference | R22: N | U22: Text: kredit modal kerja tumbuh 46,37% (yoy) Tw IV-2012; kredit investasi semakin melambat hingga Tw IV-2012. Grafik 3.4 confirms modal kerja ~45% vs investasi ~0%. | V22: Core comparison right (modal kerja growth higher than investasi), but question is garbled ('kredit modal', unclear if level or growth) and answer lacks supporting figure. | W22: Bagaimana pertumbuhan kredit modal kerja dibandingkan kredit investasi pada triwulan IV-2012? | X22: Pertumbuhan kredit modal kerja lebih tinggi, yaitu 46,37% (yoy), sementara pertumbuhan kredit investasi semakin melambat hingga triwulan IV-2012. | Y22: 0 | Z22: 0 | AA22: 0 | AB22: 0 | AC22: 0 | AD22: 0 | AE22: 1 | AF22: 0 | AG22: 0 | AH22: 1
A23: QA0022 | B23: InternVL | C23: KERProvinsiKalimantanTengahTriwulanIV2012 | D23: 42 | E23: 8dabadfb728f43cf89fe3bf6bb7614a3KERProvinsiKalimantanTengahTriwulanIV2012_p042.png | F23: 0 | G23: Text-Text Inference | H23: Text | I23: Kapital umum KER pada periode IV-2012 berapa? | J23: Rp 3,38 triliun | K23: pendek | L23: REVISE | M23: Minor | N23: Typo/Grammar | O23: Typo/Grammar | P23: Y | Q23: Text-Text Inference | R23: Y | U23: Text: penyaluran kredit UMKM Tw IV-2012 tercatat Rp3,38 triliun (23,7% dari total kredit perbankan). | V23: Value Rp3,38 triliun is correct for UMKM credit, but question is garbled ('Kapital umum KER') and does not name UMKM credit. | W23: Berapa penyaluran kredit UMKM di Kalimantan Tengah pada triwulan IV-2012? | X23: Rp3,38 triliun | Y23: 0 | Z23: 0 | AA23: 0 | AB23: 0 | AC23: 0 | AD23: 0 | AE23: 0 | AF23: 0 | AG23: 0 | AH23: 1
A24: QA0023 | B24: InternVL | C24: KERProvinsiKalimantanTengahTriwulanIV2012 | D24: 42 | E24: 8dabadfb728f43cf89fe3bf6bb7614a3KERProvinsiKalimantanTengahTriwulanIV2012_p042.png | F24: 1 | G24: Table-Numerical Calculation | H24: Table | I24: Bagaimana berubah kredit umum KER dari periode IV-2011 hingga IV-2012? | J24: Kredit umum KER meningkat dari 2,612,917 juta menjadi 3,387,552 juta | K24: panjang | L24: REVISE | M24: Minor | N24: Typo/Grammar | O24: Typo/Grammar, Incomplete | P24: Y | Q24: Table-Numerical Calculation | R24: N | U24: Tabel 3.5 Kredit UMKM (Rp juta): Tw IV-2011 2,612,917; Tw IV-2012 3,387,552 (growth 29,65% yoy, also in text). | V24: Values correct but question garbled ('kredit umum KER' = kredit UMKM), unit label incomplete (Rp juta), and no growth computed despite calculation category. | W24: Bagaimana perubahan kredit UMKM Kalimantan Tengah dari Tw IV-2011 ke Tw IV-2012? | X24: Kredit UMKM meningkat dari Rp2.612.917 juta (Tw IV-2011) menjadi Rp3.387.552 juta (Tw IV-2012), tumbuh sekitar 29,65% (yoy). | Y24: 0 | Z24: 0 | AA24: 0 | AB24: 0 | AC24: 0 | AD24: 0 | AE24: 1 | AF24: 0 | AG24: 0 | AH24: 1
A25: QA0024 | B25: InternVL | C25: KERProvinsiKalimantanTengahTriwulanIV2012 | D25: 42 | E25: 8dabadfb728f43cf89fe3bf6bb7614a3KERProvinsiKalimantanTengahTriwulanIV2012_p042.png | F25: 2 | G25: Chart-Information Extraction | H25: Chart | I25: Persentase pertumbuhan kredit umum KER hingga IV-2012 berapa? | J25: 23,7% | K25: pendek | L25: REVISE | M25: Major | N25: Factual/Numerical | O25: Factual/Numerical, Instruction-following, Typo/Grammar | P25: N | Q25: Text-Text Inference | R25: N | U25: Text: pertumbuhan kredit UMKM meningkat dari 26,17% menjadi 29,65% (yoy); 23,7% is pangsa kredit UMKM to total kredit. | V25: 23,7% is the share of UMKM credit in total bank credit, not growth; growth is 29,65% yoy. No chart on page (text/table). | W25: Berapa pertumbuhan kredit UMKM Kalimantan Tengah pada triwulan IV-2012? | X25: 29,65% (yoy), meningkat dari 26,17% pada triwulan sebelumnya. | Y25: 0 | Z25: 1 | AA25: 0 | AB25: 0 | AC25: 0 | AD25: 0 | AE25: 0 | AF25: 1 | AG25: 0 | AH25: 1
A26: QA0025 | B26: InternVL | C26: KERProvinsiKalimantanTengahTriwulanIV2012 | D26: 44 | E26: 8dabadfb728f43cf89fe3bf6bb7614a3KERProvinsiKalimantanTengahTriwulanIV2012_p044.png | F26: 0 | G26: Chart-Time-Sensitive | H26: Chart | I26: Bagaimana perubahan jumlah uang yang masuk ke Bank Indonesia selama periode 2007-2012? | J26: Jumlah uang yang masuk ke Bank Indonesia meningkat dari 2007 hingga 2012, dengan kemampuan tertinggi di tahun 2011. | K26: pendek | L26: DISCARD | M26: Critical | N26: Hallucination | O26: Hallucination | P26: N | Q26: Chart-Time-Sensitive | R26: N | S26: Period/time comparison not on page | T26: Fabricated value/claim (not on page) | U26: Page charts only PTTB (Rp miliar) and Rasio PTTB thd Inflow (Grafik 3.10); inflow amounts are not shown anywhere. | V26: Inflow values for 2007-2012 are not on the page; the claimed rise peaking in 2011 has no support. | Y26: 1 | Z26: 0 | AA26: 0 | AB26: 0 | AC26: 0 | AD26: 0 | AE26: 0 | AF26: 0 | AG26: 0 | AH26: 0
A27: QA0026 | B27: InternVL | C27: KERProvinsiKalimantanTengahTriwulanIV2012 | D27: 44 | E27: 8dabadfb728f43cf89fe3bf6bb7614a3KERProvinsiKalimantanTengahTriwulanIV2012_p044.png | F27: 1 | G27: Chart-Numerical Calculation | H27: Chart | I27: Bagaimana perubahan rasio PTBT terhadap inflow selama periode 2007-2012? | J27: Rasio PTBT terhadap inflow meningkat dari 2007 hingga 2012, dengan kemampuan tertinggi di tahun 2011. | K27: panjang | L27: REVISE | M27: Major | N27: Reasoning | O27: Reasoning, Instruction-following, Typo/Grammar | P27: N | Q27: Chart-Time-Sensitive | R27: N | U27: Grafik 3.10: ratio fluctuates, ~7,5% (Tw I-2007), peaks ~26% Tw II-2007 and ~30% Tw IV-2011, drops to ~1% Tw II-2012, ~4% Tw IV-2012. | V27: The ratio did not rise steadily; it fluctuated and ended 2012 below 2007. Peak in 2011 (Tw IV) is right. It is a trend question, not a calculation. 'PTBT' is a typo. | W27: Bagaimana perubahan rasio PTTB terhadap inflow selama periode 2007-2012? | X27: Rasio PTTB terhadap inflow berfluktuasi selama 2007-2012, dengan puncak tertinggi sekitar 30% pada triwulan IV-2011, lalu turun tajam menjadi sekitar 1% pada triwulan II-2012 dan sekitar 4% pada triwulan IV-2012. | Y27: 0 | Z27: 0 | AA27: 0 | AB27: 1 | AC27: 0 | AD27: 0 | AE27: 0 | AF27: 1 | AG27: 0 | AH27: 1
A28: QA0027 | B28: InternVL | C28: KERProvinsiKalimantanTengahTriwulanIV2012 | D28: 44 | E28: 8dabadfb728f43cf89fe3bf6bb7614a3KERProvinsiKalimantanTengahTriwulanIV2012_p044.png | F28: 2 | G28: Chart-Information Extraction | H28: Chart | I28: Bagaimana perubahan jumlah uang yang dijelajahi oleh Bank Indonesia selama periode 2007-2012? | J28: Jumlah uang yang dijelajahi oleh Bank Indonesia meningkat dari 2007 hingga 2012, dengan kemampuan tertinggi di tahun 2011. | K28: pendek | L28: DISCARD | M28: Critical | N28: Hallucination | O28: Hallucination, Typo/Grammar | P28: N | Q28: Chart-Information Extraction | R28: N | S28: Garbled/unintelligible question | T28: Non-answer (no factual content) | U28: The page has no 'uang yang dijelajahi' metric; charts show PTTB and ratio/growth of PTTB. | V28: The question is garbled ('dijelajahi') and refers to no metric on the page; the answer is boilerplate with no support. | Y28: 1 | Z28: 0 | AA28: 0 | AB28: 0 | AC28: 0 | AD28: 0 | AE28: 0 | AF28: 0 | AG28: 0 | AH28: 1
A29: QA0028 | B29: InternVL | C29: KERProvinsiKalimantanTengahTriwulanIV2012 | D29: 47 | E29: 8dabadfb728f43cf89fe3bf6bb7614a3KERProvinsiKalimantanTengahTriwulanIV2012_p047.png | F29: 0 | G29: Text-Text Inference | H29: Text | I29: Bagaimana hasil kontribusi anggaran pemerintah pada tahun 2011 dan 2012? | J29: Kontribusi anggaran pemerintah pada tahun 2011 sebesar 528,49 miliar, pada tahun 2012 sebesar 528,49 miliar | K29: pendek | L29: REVISE | M29: Major | N29: Factual/Numerical | O29: Factual/Numerical, Temporal, Typo/Grammar, Instruction-following | P29: N | Q29: Table-Comparison and Sorting | R29: N | U29: Tabel 4.1: Surplus/(Defisit) 2011 (581.246) juta, 2012 (528.494) juta; text: defisit 2012 Rp528,49 miliar. | V29: Vague 'kontribusi anggaran pemerintah'; 528,49 miliar is the 2012 deficit only, 2011 deficit was Rp581,25 miliar. Same value for both years is wrong; data is from table. | W29: Berapa defisit APBD Kalimantan Tengah pada tahun 2011 dan 2012? | X29: Defisit APBD Kalimantan Tengah sebesar Rp581,25 miliar pada tahun 2011 dan Rp528,49 miliar pada tahun 2012. | Y29: 0 | Z29: 1 | AA29: 0 | AB29: 0 | AC29: 1 | AD29: 0 | AE29: 0 | AF29: 1 | AG29: 0 | AH29: 1
A30: QA0029 | B30: InternVL | C30: KERProvinsiKalimantanTengahTriwulanIV2012 | D30: 47 | E30: 8dabadfb728f43cf89fe3bf6bb7614a3KERProvinsiKalimantanTengahTriwulanIV2012_p047.png | F30: 1 | G30: Chart-Numerical Calculation | H30: Chart | I30: Bagaimana berlakulah pengeluaran APBD pada tahun 2011 dan 2012? | J30: Pada tahun 2011, pengeluaran APBD sebesar 47,42 miliar, pada tahun 2012, sebesar 47,42 miliar | K30: panjang | L30: REVISE | M30: Major | N30: Factual/Numerical | O30: Factual/Numerical, Temporal, Typo/Grammar, Instruction-following | P30: N | Q30: Table-Comparison and Sorting | R30: N | U30: Tabel 4.1 Total Belanja: 10.103.457 juta (2011), 11.603.391 juta (2012); 47,42 miliar = hasil pengelolaan kekayaan daerah 2012 (text). | V30: 47,42 miliar is not APBD expenditure; total belanja was Rp10,10 T (2011) and Rp11,60 T (2012). Garbled question; no chart on page. | W30: Berapa total belanja APBD Kalimantan Tengah pada tahun 2011 dan 2012? | X30: Total belanja APBD Kalimantan Tengah sebesar Rp10,10 triliun (Rp10.103.457 juta) pada 2011 dan Rp11,60 triliun (Rp11.603.391 juta) pada 2012. | Y30: 0 | Z30: 1 | AA30: 0 | AB30: 0 | AC30: 1 | AD30: 0 | AE30: 0 | AF30: 1 | AG30: 0 | AH30: 1
A31: QA0030 | B31: InternVL | C31: KERProvinsiKalimantanTengahTriwulanIV2012 | D31: 47 | E31: 8dabadfb728f43cf89fe3bf6bb7614a3KERProvinsiKalimantanTengahTriwulanIV2012_p047.png | F31: 2 | G31: Chart-Information Extraction | H31: Chart | I31: Bagaimana berlakulah keuangan daerah pada tahun 2011 dan 2012? | J31: Pada tahun 2011, keuangan daerah sebesar 126,6 miliar, pada tahun 2012, sebesar 126,6 miliar | K31: pendek | L31: REVISE | M31: Major | N31: Factual/Numerical | O31: Factual/Numerical, Typo/Grammar, Temporal, Instruction-following | P31: N | Q31: Table-Comparison and Sorting | R31: N | U31: Text: retribusi daerah 2012 Rp126,6 miliar (no 2011 value). Tabel 4.1 Total Pendapatan 9.522.211 juta (2011), 11.074.897 juta (2012). | V31: Question garbled/vague; 126,6 miliar is only the 2012 retribusi target, repeated for 2011. No chart. Rewritten as total pendapatan from Tabel 4.1. | W31: Berapa total pendapatan APBD Kalimantan Tengah pada tahun 2011 dan 2012? | X31: Total pendapatan APBD Kalimantan Tengah sebesar Rp9,52 triliun (Rp9.522.211 juta) pada 2011 dan Rp11,07 triliun (Rp11.074.897 juta) pada 2012. | Y31: 0 | Z31: 1 | AA31: 0 | AB31: 0 | AC31: 1 | AD31: 0 | AE31: 0 | AF31: 1 | AG31: 0 | AH31: 1
A32: QA0031 | B32: InternVL | C32: KERProvinsiKalimantanTengahTriwulanIV2012 | D32: 53 | E32: 8dabadfb728f43cf89fe3bf6bb7614a3KERProvinsiKalimantanTengahTriwulanIV2012_p053.png | F32: 0 | G32: Text-Text Inference | H32: Text | I32: Bagaimana kondisi kesejahteraan masyarakat Kaliemantan Tengah pada bulan Desember 2012? | J32: Kondisi kesejahteraan masyarakat Kaliemantan Tengah pada bulan Desember 2012 meningkat sekitar 98,66% dibandingkan bulan sebelumnya. | K32: pendek | L32: REVISE | M32: Major | N32: Reasoning | O32: Reasoning, Factual/Numerical, Unit, Typo/Grammar | P32: Y | Q32: Text-Text Inference | R32: N | U32: Text: Indeks NTP Desember 2012 sebesar 98,66, lebih rendah dari triwulan sebelumnya 98,95; kesejahteraan petani menurun. | V32: Direction wrong (welfare fell, not rose) and 98,66 is the NTP index level, not a % increase. 'Kaliemantan' typo. | W32: Bagaimana kondisi kesejahteraan petani Kalimantan Tengah pada bulan Desember 2012? | X32: Kesejahteraan petani menurun; indeks NTP Desember 2012 tercatat 98,66, lebih rendah dari triwulan sebelumnya (98,95) dan masih berada di area defisit (<100). | Y32: 0 | Z32: 1 | AA32: 0 | AB32: 1 | AC32: 0 | AD32: 1 | AE32: 0 | AF32: 0 | AG32: 0 | AH32: 1
A33: QA0032 | B33: InternVL | C33: KERProvinsiKalimantanTengahTriwulanIV2012 | D33: 53 | E33: 8dabadfb728f43cf89fe3bf6bb7614a3KERProvinsiKalimantanTengahTriwulanIV2012_p053.png | F33: 1 | G33: Chart-Time-Sensitive | H33: Chart | I33: Bagaimana perubahan kesejahteraan masyarakat Kaliemantan Tengah selama periode tiga tahun terakhir? | J33: Kesejahteraan masyarakat Kaliemantan Tengah meningkat sekitar 0,1% setiap tahun selama periode tiga tahun terakhir. | K33: panjang | L33: REVISE | M33: Major | N33: Factual/Numerical | O33: Temporal, Factual/Numerical, Instruction-following, Typo/Grammar | P33: N | Q33: Text-Text Inference | R33: N | U33: Text: dalam 10 tahun terakhir laju pertumbuhan ekonomi naik 4,91% -> 6,26% (rata-rata 0,1%/tahun); persentase penduduk miskin turun rata-rata 0,54%/tahun. | V33: 0,1% per year refers to economic growth over 10 years, not welfare over 3 years; evidence is text, not chart. | W33: Bagaimana perubahan kesejahteraan masyarakat Kalimantan Tengah dalam 10 tahun terakhir? | X33: Kesejahteraan membaik: persentase penduduk miskin turun rata-rata 0,54% per tahun (dari hampir 12% pada 2003 menjadi 6,51% pada Maret 2012), seiring pertumbuhan ekonomi yang naik dari 4,91% menjadi 6,26%. | Y33: 0 | Z33: 1 | AA33: 0 | AB33: 0 | AC33: 1 | AD33: 0 | AE33: 0 | AF33: 1 | AG33: 0 | AH33: 1
A34: QA0033 | B34: InternVL | C34: KERProvinsiKalimantanTengahTriwulanIV2012 | D34: 53 | E34: 8dabadfb728f43cf89fe3bf6bb7614a3KERProvinsiKalimantanTengahTriwulanIV2012_p053.png | F34: 2 | G34: Table-Numerical Calculation | H34: Table | I34: Bagaimana kesejahteraan masyarakat Kaliemantan Tengah pada bulan Desember 2011? | J34: Kesejahteraan masyarakat Kaliemantan Tengah pada bulan Desember 2011 adalah 98,95. | K34: pendek | L34: DISCARD | M34: Critical | N34: Hallucination | O34: Hallucination, Temporal | P34: N | Q34: Table-Comparison and Sorting | R34: N | S34: Period/time comparison not on page | T34: Borrowed value from another metric on the page | U34: Tabel 5.2 only covers Jun-12, Sep-12, Des-12; NTP Sep-12 = 98,95. No December 2011 data on page. | V34: December 2011 NTP/welfare is not on the page; 98,95 is Sep-12 value. | Y34: 1 | Z34: 0 | AA34: 0 | AB34: 0 | AC34: 1 | AD34: 0 | AE34: 0 | AF34: 0 | AG34: 0 | AH34: 0
A35: QA0034 | B35: InternVL | C35: Buletin - Beyond Infinity Edisi Desember 2025 | D35: 9 | E35: Buletin 20- 20Beyond 20Infinity 20Edisi 20Desember 202025_p009.png | F35: 0 | G35: Text-Text Inference | H35: Text | I35: Mengapa ada banyak kapal di luar pantai? | J35: Untuk mendukung industri minyak dan gas | K35: pendek | L35: DISCARD | M35: Critical | N35: Hallucination | O35: Hallucination | P35: N | Q35: Text-Text Inference | R35: N | S35: False premise / speculation | T35: Fabricated value/claim (not on page) | U35: Page is a photo of an offshore rig with two supply boats plus 'Inspirasi' (book list) and 'Penulis' (author bio) boxes; no text explains the ships. | V35: No text on the page explains why ships are offshore; the answer is speculation from the photo, not grounded in document content. | Y35: 1 | Z35: 0 | AA35: 0 | AB35: 0 | AC35: 0 | AD35: 0 | AE35: 0 | AF35: 0 | AG35: 0 | AH35: 0
A36: QA0035 | B36: InternVL | C36: Buletin - Beyond Infinity Edisi Desember 2025 | D36: 9 | E36: Buletin 20- 20Beyond 20Infinity 20Edisi 20Desember 202025_p009.png | F36: 1 | G36: Chart-Information Extraction | H36: Chart | I36: Bagaimana industri minyak dan gas menghubungkan dengan ekonomi Indonesia? | J36: Industri minyak dan gas memberikan kontribusi besar untuk pembangunan ekonomi Indonesia, termasuk melalui pembangunan daerah dan pembangunan teknologi. | K36: panjang | L36: DISCARD | M36: Critical | N36: Hallucination | O36: Hallucination, Instruction-following | P36: N | Q36: Text-Text Inference | R36: N | S36: Metric/topic not on page | T36: Fabricated value/claim (not on page) | U36: No chart and no text about the oil and gas industry's contribution to the Indonesian economy; only a photo, book list and author bio. | V36: Topic (oil & gas contribution to regional/technology development) is not on the page; there is no chart either. | Y36: 1 | Z36: 0 | AA36: 0 | AB36: 0 | AC36: 0 | AD36: 0 | AE36: 0 | AF36: 1 | AG36: 0 | AH36: 0
A37: QA0036 | B37: InternVL | C37: Buletin - Beyond Infinity Edisi Desember 2025 | D37: 9 | E37: Buletin 20- 20Beyond 20Infinity 20Edisi 20Desember 202025_p009.png | F37: 2 | G37: Chart-Numerical Calculation | H37: Chart | I37: Penggunaan kapal di luar pantai berdasarkan dokumen? | J37: Dokumen tidak menyediakan informasi numerik | K37: pendek | L37: DISCARD | M37: Critical | N37: Hallucination | O37: Hallucination, Typo/Grammar, Instruction-following | P37: N | Q37: Text-Text Inference | R37: N | S37: Garbled/unintelligible question | T37: Non-answer (no factual content) | U37: No chart or numeric data on ship usage; page has only a photo, book list and author bio. | V37: Garbled question about ship usage has no grounding; no chart or numbers exist, answer is a non-answer. | Y37: 1 | Z37: 0 | AA37: 0 | AB37: 0 | AC37: 0 | AD37: 0 | AE37: 0 | AF37: 1 | AG37: 0 | AH37: 1
A38: QA0037 | B38: InternVL | C38: Buletin - Beyond Infinity Edisi Desember 2025 | D38: 21 | E38: Buletin 20- 20Beyond 20Infinity 20Edisi 20Desember 202025_p021.png | F38: 0 | G38: Chart-Information Extraction | H38: Chart | I38: Jumlah penyelenggaran ITSK terdafar pada bulan Juni 2025 berapa? | J38: 30 | K38: pendek | L38: REVISE | M38: Minor | N38: Format | O38: Format, Typo/Grammar | P38: Y | Q38: Chart-Information Extraction | R38: Y | U38: Chart 'Perkembangan Jumlah Penyelenggara ITSK': Terdaftar (yellow) Jun = 30; text: total 30 terdiri dari 10 PKA dan 20 PAJK. | V38: Value 30 is correct, but answer is a bare number without context and question has typos (penyelenggaran, terdafar). | W38: Berapa jumlah penyelenggara ITSK terdaftar pada bulan Juni 2025? | X38: Jumlah penyelenggara ITSK terdaftar pada Juni 2025 sebanyak 30, terdiri dari 10 PKA dan 20 PAJK. | Y38: 0 | Z38: 0 | AA38: 0 | AB38: 0 | AC38: 0 | AD38: 0 | AE38: 0 | AF38: 0 | AG38: 1 | AH38: 1
A39: QA0038 | B39: InternVL | C39: Buletin - Beyond Infinity Edisi Desember 2025 | D39: 21 | E39: Buletin 20- 20Beyond 20Infinity 20Edisi 20Desember 202025_p021.png | F39: 1 | G39: Chart-Time-Sensitive | H39: Chart | I39: Bagaimana perkembangan jumlah penyelenggaran ITSK dari bulan Januari hingga Juni 2025? | J39: Jumlah penyelenggaran ITSK meningkat secara konsisten dari bulan Januari hingga Juni 2025, dengan jumlah terbesar pada bulan Juni 2025. | K39: panjang | L39: PASS | M39: None | N39: None | P39: Y | Q39: Chart-Time-Sensitive | R39: Y | U39: Terdaftar bars Jan-Jun 2025: 17, 21, 26, 28, 29, 30 - rising every month, peak in June. | V39: Consistent increase with maximum in June matches the chart; trend category fits. | Y39: 0 | Z39: 0 | AA39: 0 | AB39: 0 | AC39: 0 | AD39: 0 | AE39: 0 | AF39: 0 | AG39: 0 | AH39: 0
A40: QA0039 | B40: InternVL | C40: Buletin - Beyond Infinity Edisi Desember 2025 | D40: 21 | E40: Buletin 20- 20Beyond 20Infinity 20Edisi 20Desember 202025_p021.png | F40: 2 | G40: Chart-Numerical Calculation | H40: Chart | I40: Bagaimana perkembangan total aset penyelenggaran ITSK terdafar dari bulan Januari hingga November 2025? | J40: Total aset penyelenggaran ITSK terdafar meningkat dari 106,27 juta pada bulan Januari 2025 menjadi 476,15 juta pada bulan November 2025. | K40: pendek | L40: REVISE | M40: Major | N40: Factual/Numerical | O40: Factual/Numerical, Unit, Instruction-following | P40: N | Q40: Chart-Time-Sensitive | R40: N | U40: Total Aset chart (Rp Miliar): PKA 379,47 (Jan) -> 476,15 (Nov); PAJK 106,27 (Jan) -> 185,25 (Nov). | V40: Answer mixes series (106,27 is PAJK Jan, 476,15 is PKA Nov) and uses 'juta' instead of Rp miliar; question is a trend description, not a calculation. | X40: Total aset PKA terdaftar naik dari Rp379,47 miliar (Januari 2025) menjadi Rp476,15 miliar (November 2025), sedangkan total aset PAJK terdaftar naik dari Rp106,27 miliar menjadi Rp185,25 miliar. | Y40: 0 | Z40: 1 | AA40: 0 | AB40: 0 | AC40: 0 | AD40: 1 | AE40: 0 | AF40: 1 | AG40: 0 | AH40: 0
...

Sheet By_Category
A1: Metrics per QA category and modality (Text / Chart / Table)
A2: Category = category assigned by the generator. Rates are % of QA in that row.
A4: Model | B4: Group | C4: Category / Modality | D4: N | E4: PASS | F4: REVISE | G4: DISCARD | H4: Content correct | I4: QA Accuracy | J4: Revision Rate | K4: Discard Rate | L4: FPY | M4: Error Rate | N4: Minor | O4: Major | P4: Critical | Q4: Category label correct % | R4: Top error: Factual/Numerical | S4: Reasoning | T4: Temporal | U4: Calculation | V4: Incomplete | W4: Unit | X4: Instruction-following | Y4: Typo/Grammar | Z4: Format | AA4: Hallucination
